Sim, uma exceção pode ser lançada após ser capturada. Isso demonstra que pode ocorrer mais de uma exceção dentro do código. 